Workbook

Sheet Dashboard
A1: Sales Performance Dashboard
A3: Total Sales | D3: Total Profit | G3: Quantity Sold | J3: Average Order Value
A4: =Analysis!M15 -> 49437.38 | D4: =Analysis!M18 -> 13119.5 | G4: =Analysis!M21 -> 824 | J4: =Analysis!M24 -> 279.30723

Sheet Raw Data
A1: Order ID | B1: Order Date | C1: Customer | D1: Region | E1: Product | F1: Category | G1: Quantity | H1: Unit Price | I1: Discount | J1: Sales | K1: Profit
A2: ORD-0001 | B2: 45760 | C2: Customer 058 | D2: East | E2: Monitor | F2: Displays | G2: 4 | H2: 225.14 | I2: 0.1 | J2: 810.52 | K2: 210.95
A3: ORD-0002 | B3: 45788 | C3: Customer 022 | D3: North | E3: Monitor | F3: Displays | G3: 3 | H3: 208.63 | I3: 0 | J3: 625.89 | K3: 219.96
A4: ORD-0003 | B4: 45934 | C4: Customer 033 | D4: West | E4: Wireless Mouse | F4: Accessories | G4: 8 | H4: 23.17 | I4: 0 | J4: 185.36 | K4: 63.7
A5: ORD-0004 | B5: 45827 | C5: Customer 028 | D5: West | E5: Wireless Mouse | F5: Accessories | G5: 6 | H5: 20.26 | I5: 0 | J5: 121.59 | K5: 33.44
A6: ORD-0005 | B6: 45712 | C6: Customer 052 | D6: West | E6: Desk Lamp | F6: Office | G6: 7 | H6: 31.78 | I6: 0.1 | J6: 200.18 | K6: 68.08
A7: ORD-0006 | B7: 45931 | C7: Customer 004 | D7: North | E7: Laptop Stand | F7: Accessories | G7: 3 | H7: 37.02 | I7: 0.05 | J7: 105.49 | K7: 30.58
A8: ORD-0007 | B8: 45997 | C8: Customer 028 | D8: East | E8: USB-C Hub | F8: Accessories | G8: 6 | H8: 40.92 | I8: 0 | J8: 245.55 | K8: 88.51
A9: ORD-0008 | B9: 45738 | C9: Customer 036 | D9: North | E9: USB-C Hub | F9: Accessories | G9: 7 | H9: 39.69 | I9: 0.1 | J9: 250.02 | K9: 86.34
A10: ORD-0009 | B10: 45967 | C10: Customer 029 | D10: East | E10: Desk Lamp | F10: Office | G10: 4 | H10: 31.04 | I10: 0.05 | J10: 117.94 | K10: 31.92
A11: ORD-0010 | B11: 46008 | C11: Customer 048 | D11: East | E11: Wireless Mouse | F11: Accessories | G11: 2 | H11: 21.82 | I11: 0.05 | J11: 41.46 | K11: 8.07
A12: ORD-0011 | B12: 45865 | C12: Customer 045 | D12: South | E12: Desk Lamp | F12: Office | G12: 6 | H12: 30.44 | I12: 0 | J12: 182.66 | K12: 57.53
A13: ORD-0012 | B13: 45698 | C13: Customer 029 | D13: East | E13: Monitor | F13: Displays | G13: 5 | H13: 212.91 | I13: 0.15 | J13: 904.89 | K13: 234
... A144: ORD-0142 | B144: 45806 | C144: Customer 047 | D144: North | E144: Headset | F144: Audio | G144: 7 | H144: 69.38 | I144: 0.1 | J144: 437.07 | K144: 120.73
A145: ORD-0143 | B145: 45948 | C145: Customer 052 | D145: North | E145: Webcam | F145: Accessories | H145: 52.41 | I145: 0.1 | J145: 47.17 | K145: 12.23
A146: ORD-0144 | B146: 46004 | C146: Customer 017 | D146: West | E146: Wireless Mouse | F146: Accessories | G146: 3 | H146: 23.49 | I146: 0.05 | J146: 66.94 | K146: 19
A147: ORD-0145 | B147: 45837 | C147: Customer 006 | D147: North | E147: Keyboard | F147: Accessories | G147: 3 | H147: 47.63 | I147: 0 | J147: 142.9 | K147: 49.26
A148: ORD-0146 | B148: 45813 | C148: Customer 050 | D148: North | E148: Desk Lamp | F148: Office | G148: 1 | H148: 31.3 | I148: 0.05 | J148: 29.73 | K148: 7.54
A149: ORD-0147 | B149: 45999 | C149: Customer 028 | D149: East | E149: Laptop Stand | F149: Accessories | G149: 7 | H149: 37.66 | I149: 0.05 | J149: 250.46 | K149: 67.26
A150: ORD-0148 | B150: 45872 | C150: Customer 051 | D150: East | E150: Webcam | F150: Accessories | G150: 8 | H150: 55.02 | I150: 0.05 | J150: 418.15 | K150: 153.29
A151: ORD-0149 | B151: 45943 | C151: Customer 016 | D151: West | E151: Desk Lamp | F151: Office | G151: 3 | H151: 31.23 | I151: 0.05 | J151: 89 | K151: 22.7
A152: ORD-0150 | B152: 45770 | C152: Customer 050 | D152: South | E152: Keyboard | F152: Accessories | G152: 2 | H152: 46.42 | I152: 0.1 | J152: 83.55 | K152: 22.93
A153: ORD-0151 | B153: 46016 | C153: Customer 003 | D153: West | E153: Headset | F153: Audio | G153: 3 | H153: 61.41 | I153: 0 | J153: 184.24 | K153: 38.26
A154: ORD-0152 | B154: 45712 | C154: Customer 028 | D154: West | E154: Wireless Mouse | F154: Accessories | G154: 2 | H154: 23.4 | I154: 0.05 | J154: 44.46 | K154: 9.77
A155: ORD-0153 | B155: 45912 | C155: Customer 008 | D155: South | E155: Wireless Mouse | F155: Accessories | G155: 7 | H155: 22.56 | I155: 0 | J155: 157.92 | K155: 53
A156: ORD-0154 | B156: 45921 | C156: Customer 034 | D156: East | E156: Laptop Stand | F156: Accessories | G156: 7 | H156: 35.39 | I156: 0.1 | J156: 222.95 | K156: 59.9
A157: ORD-0155 | B157: 45822 | C157: Customer 054 | D157: North | E157: Desk Lamp | F157: Office | G157: 8 | H157: 33.14 | I157: 0.1 | J157: 238.59 | K157: 51.05
... A167: ORD-0165 | B167: 45894 | C167: Customer 057 | D167: North | E167: Keyboard | F167: Accessories | G167: 1 | H167: 46.21 | I167: 0.1 | J167: 41.59 | K167: 13.72
A168: ORD-0166 | C168: Customer 046 | D168: West | E168: Monitor | F168: Displays | G168: 2 | H168: 223.92 | I168: 0.05 | J168: 425.46 | K168: 129.07
A169: ORD-0167 | B169: 45939 | C169: Customer 029 | D169: North | E169: Wireless Mouse | F169: Accessories | G169: 4 | H169: 23.61 | I169: 0 | J169: 94.46 | K169: 34.19
A170: ORD-0168 | B170: 45889 | C170: Customer 035 | D170: South | E170: Keyboard | F170: Accessories | G170: 8 | H170: 47.52 | I170: 0.1 | J170: 342.13 | K170: 80.64
A171: ORD-0169 | B171: 45946 | C171: Customer 058 | D171: West | E171: Wireless Mouse | F171: Accessories | G171: 7 | H171: 22.58 | I171: 0.15 | J171: 134.33 | K171: 31.36
A172: ORD-0170 | B172: 46022 | C172: Customer 043 | D172: South | E172: Monitor | F172: Displays | G172: 4 | H172: 198.64 | I172: 0.1 | J172: 715.12 | K172: 150.69
A173: ORD-0171 | B173: 45786 | C173: Customer 025 | D173: North | E173: Laptop Stand | F173: Accessories | G173: 2 | H173: 34.86 | I173: 0 | J173: 69.71 | K173: 21.59
A174: ORD-0172 | B174: 45886 | C174: Customer 044 | D174: West | E174: Keyboard | F174: Accessories | G174: 8 | H174: 47.5 | I174: 0 | J174: 380 | K174: 82.15
A175: ORD-0173 | B175: 45962 | C175: Customer 017 | D175: South | E175: Keyboard | F175: Accessories | G175: 6 | H175: 44.2 | I175: 0 | J175: 265.2 | K175: 84.09
A176: ORD-0174 | B176: 45996 | C176: Customer 008 | D176: East | E176: Laptop Stand | F176: Accessories | G176: 7 | H176: 35.12 | I176: 0 | J176: 245.83 | K176: 46.31
A177: ORD-0175 | B177: 45682 | C177: Customer 018 | D177: North | E177: Webcam | F177: Accessories | G177: 1 | H177: 56.4 | I177: 0.05 | J177: 53.58 | K177: 11.26
A178: ORD-0176 | B178: 45945 | C178: Customer 010 | D178: West | E178: USB-C Hub | F178: Accessories | G178: 7 | H178: 40.21 | I178: 0 | J178: 281.44 | K178: 69.24
A179: ORD-0177 | B179: 45927 | C179: Customer 015 | D179: North | E179: Monitor | F179: Displays | G179: 1 | H179: 199.27 | I179: 0.05 | J179: 189.3 | K179: 37.27
...

Sheet Cleaned Data
A1: Order ID | B1: Order Date | C1: Customer | D1: Region | E1: Product | F1: Category | G1: Quantity | H1: Unit Price | I1: Discount | J1: Sales | K1: Profit
A2: ORD-0001 | B2: 45760 | C2: Customer 058 | D2: East | E2: Monitor | F2: Displays | G2: 4 | H2: 225.14 | I2: 0.1 | J2: 810.52 | K2: 210.95 | M2: data change notes
A3: ORD-0002 | B3: 45788 | C3: Customer 022 | D3: North | E3: Monitor | F3: Displays | G3: 3 | H3: 208.63 | I3: 0 | J3: 625.89 | K3: 219.96 | M3: 1 ord 0021 duplicate
A4: ORD-0003 | B4: 45934 | C4: Customer 033 | D4: West | E4: Wireless Mouse | F4: Accessories | G4: 8 | H4: 23.17 | I4: 0 | J4: 185.36 | K4: 63.7 | M4: 2. ord 0166 missing order date
A5: ORD-0004 | B5: 45827 | C5: Customer 028 | D5: West | E5: Wireless Mouse | F5: Accessories | G5: 6 | H5: 20.26 | I5: 0 | J5: 121.59 | K5: 33.44 | M5: 3. ord 0143 missing quantity
A6: ORD-0005 | B6: 45712 | C6: Customer 052 | D6: West | E6: Desk Lamp | F6: Office | G6: 7 | H6: 31.78 | I6: 0.1 | J6: 200.18 | K6: 68.08 | M6: 4. ord 0117 missing discount Assumed 0
A7: ORD-0006 | B7: 45931 | C7: Customer 004 | D7: North | E7: Laptop Stand | F7: Accessories | G7: 3 | H7: 37.02 | I7: 0.05 | J7: 105.49 | K7: 30.58
A8: ORD-0007 | B8: 45997 | C8: Customer 028 | D8: East | E8: USB-C Hub | F8: Accessories | G8: 6 | H8: 40.92 | I8: 0 | J8: 245.55 | K8: 88.51
A9: ORD-0008 | B9: 45738 | C9: Customer 036 | D9: North | E9: USB-C Hub | F9: Accessories | G9: 7 | H9: 39.69 | I9: 0.1 | J9: 250.02 | K9: 86.34
A10: ORD-0009 | B10: 45967 | C10: Customer 029 | D10: East | E10: Desk Lamp | F10: Office | G10: 4 | H10: 31.04 | I10: 0.05 | J10: 117.94 | K10: 31.92
A11: ORD-0010 | B11: 46008 | C11: Customer 048 | D11: East | E11: Wireless Mouse | F11: Accessories | G11: 2 | H11: 21.82 | I11: 0.05 | J11: 41.46 | K11: 8.07
A12: ORD-0011 | B12: 45865 | C12: Customer 045 | D12: South | E12: Desk Lamp | F12: Office | G12: 6 | H12: 30.44 | I12: 0 | J12: 182.66 | K12: 57.53
A13: ORD-0012 | B13: 45698 | C13: Customer 029 | D13: East | E13: Monitor | F13: Displays | G13: 5 | H13: 212.91 | I13: 0.15 | J13: 904.89 | K13: 234
A14: ORD-0013 | B14: 45793 | C14: Customer 024 | D14: East | E14: Webcam | F14: Accessories | G14: 1 | H14: 50.74 | I14: 0.05 | J14: 48.2 | K14: 14.51
A15: ORD-0014 | B15: 45918 | C15: Customer 042 | D15: East | E15: Keyboard | F15: Accessories | G15: 3 | H15: 49.59 | I15: 0.1 | J15: 133.89 | K15: 30.22
A16: ORD-0015 | B16: 45690 | C16: Customer 048 | D16: East | E16: Wireless Mouse | F16: Accessories | G16: 1 | H16: 23.46 | I16: 0.1 | J16: 21.11 | K16: 6.13
A17: ORD-0016 | B17: 45692 | C17: Customer 001 | D17: East | E17: Monitor | F17: Displays | G17: 6 | H17: 204.13 | I17: 0.1 | J17: 1102.28 | K17: 278.31
A18: ORD-0017 | B18: 45912 | C18: Customer 014 | D18: East | E18: Webcam | F18: Accessories | G18: 7 | H18: 56.88 | I18: 0.1 | J18: 358.32 | K18: 95.94
... A143: ORD-0142 | B143: 45806 | C143: Customer 047 | D143: North | E143: Headset | F143: Audio | G143: 7 | H143: 69.38 | I143: 0.1 | J143: 437.07 | K143: 120.73
A144: ORD-0143 | B144: 45948 | C144: Customer 052 | D144: North | E144: Webcam | F144: Accessories | H144: 52.41 | I144: 0.1 | J144: 47.17 | K144: 12.23
A145: ORD-0144 | B145: 46004 | C145: Customer 017 | D145: West | E145: Wireless Mouse | F145: Accessories | G145: 3 | H145: 23.49 | I145: 0.05 | J145: 66.94 | K145: 19
A146: ORD-0145 | B146: 45837 | C146: Customer 006 | D146: North | E146: Keyboard | F146: Accessories | G146: 3 | H146: 47.63 | I146: 0 | J146: 142.9 | K146: 49.26
A147: ORD-0146 | B147: 45813 | C147: Customer 050 | D147: North | E147: Desk Lamp | F147: Office | G147: 1 | H147: 31.3 | I147: 0.05 | J147: 29.73 | K147: 7.54
A148: ORD-0147 | B148: 45999 | C148: Customer 028 | D148: East | E148: Laptop Stand | F148: Accessories | G148: 7 | H148: 37.66 | I148: 0.05 | J148: 250.46 | K148: 67.26
A149: ORD-0148 | B149: 45872 | C149: Customer 051 | D149: East | E149: Webcam | F149: Accessories | G149: 8 | H149: 55.02 | I149: 0.05 | J149: 418.15 | K149: 153.29
A150: ORD-0149 | B150: 45943 | C150: Customer 016 | D150: West | E150: Desk Lamp | F150: Office | G150: 3 | H150: 31.23 | I150: 0.05 | J150: 89 | K150: 22.7
A151: ORD-0150 | B151: 45770 | C151: Customer 050 | D151: South | E151: Keyboard | F151: Accessories | G151: 2 | H151: 46.42 | I151: 0.1 | J151: 83.55 | K151: 22.93
A152: ORD-0151 | B152: 46016 | C152: Customer 003 | D152: West | E152: Headset | F152: Audio | G152: 3 | H152: 61.41 | I152: 0 | J152: 184.24 | K152: 38.26
A153: ORD-0152 | B153: 45712 | C153: Customer 028 | D153: West | E153: Wireless Mouse | F153: Accessories | G153: 2 | H153: 23.4 | I153: 0.05 | J153: 44.46 | K153: 9.77
A154: ORD-0153 | B154: 45912 | C154: Customer 008 | D154: South | E154: Wireless Mouse | F154: Accessories | G154: 7 | H154: 22.56 | I154: 0 | J154: 157.92 | K154: 53
A155: ORD-0154 | B155: 45921 | C155: Customer 034 | D155: East | E155: Laptop Stand | F155: Accessories | G155: 7 | H155: 35.39 | I155: 0.1 | J155: 222.95 | K155: 59.9
A156: ORD-0155 | B156: 45822 | C156: Customer 054 | D156: North | E156: Desk Lamp | F156: Office | G156: 8 | H156: 33.14 | I156: 0.1 | J156: 238.59 | K156: 51.05
... A166: ORD-0165 | B166: 45894 | C166: Customer 057 | D166: North | E166: Keyboard | F166: Accessories | G166: 1 | H166: 46.21 | I166: 0.1 | J166: 41.59 | K166: 13.72
A167: ORD-0166 | C167: Customer 046 | D167: West | E167: Monitor | F167: Displays | G167: 2 | H167: 223.92 | I167: 0.05 | J167: 425.46 | K167: 129.07
A168: ORD-0167 | B168: 45939 | C168: Customer 029 | D168: North | E168: Wireless Mouse | F168: Accessories | G168: 4 | H168: 23.61 | I168: 0 | J168: 94.46 | K168: 34.19
A169: ORD-0168 | B169: 45889 | C169: Customer 035 | D169: South | E169: Keyboard | F169: Accessories | G169: 8 | H169: 47.52 | I169: 0.1 | J169: 342.13 | K169: 80.64
A170: ORD-0169 | B170: 45946 | C170: Customer 058 | D170: West | E170: Wireless Mouse | F170: Accessories | G170: 7 | H170: 22.58 | I170: 0.15 | J170: 134.33 | K170: 31.36
A171: ORD-0170 | B171: 46022 | C171: Customer 043 | D171: South | E171: Monitor | F171: Displays | G171: 4 | H171: 198.64 | I171: 0.1 | J171: 715.12 | K171: 150.69
A172: ORD-0171 | B172: 45786 | C172: Customer 025 | D172: North | E172: Laptop Stand | F172: Accessories | G172: 2 | H172: 34.86 | I172: 0 | J172: 69.71 | K172: 21.59
A173: ORD-0172 | B173: 45886 | C173: Customer 044 | D173: West | E173: Keyboard | F173: Accessories | G173: 8 | H173: 47.5 | I173: 0 | J173: 380 | K173: 82.15
...

Sheet Analysis
A1: Order ID | B1: Order Date | C1: Customer | D1: Region | E1: Product | F1: Category | G1: Quantity | H1: Unit Price | I1: Discount | J1: Sales | K1: Profit
A2: ORD-0001 | B2: 45760 | C2: Customer 058 | D2: East | E2: Monitor | F2: Displays | G2: 4 | H2: 225.14 | I2: 0.1 | J2: 810.52 | K2: 210.95
A3: ORD-0002 | B3: 45788 | C3: Customer 022 | D3: North | E3: Monitor | F3: Displays | G3: 3 | H3: 208.63 | I3: 0 | J3: 625.89 | K3: 219.96
A4: ORD-0003 | B4: 45934 | C4: Customer 033 | D4: West | E4: Wireless Mouse | F4: Accessories | G4: 8 | H4: 23.17 | I4: 0 | J4: 185.36 | K4: 63.7
A5: ORD-0004 | B5: 45827 | C5: Customer 028 | D5: West | E5: Wireless Mouse | F5: Accessories | G5: 6 | H5: 20.26 | I5: 0 | J5: 121.59 | K5: 33.44
A6: ORD-0005 | B6: 45712 | C6: Customer 052 | D6: West | E6: Desk Lamp | F6: Office | G6: 7 | H6: 31.78 | I6: 0.1 | J6: 200.18 | K6: 68.08
A7: ORD-0006 | B7: 45931 | C7: Customer 004 | D7: North | E7: Laptop Stand | F7: Accessories | G7: 3 | H7: 37.02 | I7: 0.05 | J7: 105.49 | K7: 30.58
A8: ORD-0007 | B8: 45997 | C8: Customer 028 | D8: East | E8: USB-C Hub | F8: Accessories | G8: 6 | H8: 40.92 | I8: 0 | J8: 245.55 | K8: 88.51 | M8: Notes
A9: ORD-0008 | B9: 45738 | C9: Customer 036 | D9: North | E9: USB-C Hub | F9: Accessories | G9: 7 | H9: 39.69 | I9: 0.1 | J9: 250.02 | K9: 86.34 | M9: Deleted Ord 0166
A10: ORD-0009 | B10: 45967 | C10: Customer 029 | D10: East | E10: Desk Lamp | F10: Office | G10: 4 | H10: 31.04 | I10: 0.05 | J10: 117.94 | K10: 31.92 | M10: Deleted Ord 0143
A11: ORD-0010 | B11: 46008 | C11: Customer 048 | D11: East | E11: Wireless Mouse | F11: Accessories | G11: 2 | H11: 21.82 | I11: 0.05 | J11: 41.46 | K11: 8.07
A12: ORD-0011 | B12: 45865 | C12: Customer 045 | D12: South | E12: Desk Lamp | F12: Office | G12: 6 | H12: 30.44 | I12: 0 | J12: 182.66 | K12: 57.53
A13: ORD-0012 | B13: 45698 | C13: Customer 029 | D13: East | E13: Monitor | F13: Displays | G13: 5 | H13: 212.91 | I13: 0.15 | J13: 904.89 | K13: 234
A14: ORD-0013 | B14: 45793 | C14: Customer 024 | D14: East | E14: Webcam | F14: Accessories | G14: 1 | H14: 50.74 | I14: 0.05 | J14: 48.2 | K14: 14.51 | M14: Total sales
A15: ORD-0014 | B15: 45918 | C15: Customer 042 | D15: East | E15: Keyboard | F15: Accessories | G15: 3 | H15: 49.59 | I15: 0.1 | J15: 133.89 | K15: 30.22 | M15: =SUM(J2:J178) -> 49437.38
A16: ORD-0015 | B16: 45690 | C16: Customer 048 | D16: East | E16: Wireless Mouse | F16: Accessories | G16: 1 | H16: 23.46 | I16: 0.1 | J16: 21.11 | K16: 6.13
A17: ORD-0016 | B17: 45692 | C17: Customer 001 | D17: East | E17: Monitor | F17: Displays | G17: 6 | H17: 204.13 | I17: 0.1 | J17: 1102.28 | K17: 278.31 | M17: Total Profits
A18: ORD-0017 | B18: 45912 | C18: Customer 014 | D18: East | E18: Webcam | F18: Accessories | G18: 7 | H18: 56.88 | I18: 0.1 | J18: 358.32 | K18: 95.94 | M18: =SUM(K2:K178) -> 13119.5
A19: ORD-0018 | B19: 45836 | C19: Customer 032 | D19: East | E19: Keyboard | F19: Accessories | G19: 1 | H19: 49.62 | I19: 0 | J19: 49.62 | K19: 14.5
A20: ORD-0019 | B20: 45888 | C20: Customer 045 | D20: East | E20: Laptop Stand | F20: Accessories | G20: 4 | H20: 35.35 | I20: 0.05 | J20: 134.35 | K20: 47.31 | M20: Total Quantities sold
A21: ORD-0020 | B21: 45743 | C21: Customer 028 | D21: South | E21: Keyboard | F21: Accessories | G21: 5 | H21: 45.92 | I21: 0 | J21: 229.59 | K21: 73.94 | M21: =SUM(G2:G178) -> 824
A22: ORD-0021 | B22: 45765 | C22: Customer 044 | D22: West | E22: Wireless Mouse | F22: Accessories | G22: 5 | H22: 21.28 | I22: 0 | J22: 106.4 | K22: 30.72
A23: ORD-0022 | B23: 45888 | C23: Customer 033 | D23: North | E23: Headset | F23: Audio | G23: 6 | H23: 65.41 | I23: 0.1 | J23: 353.21 | K23: 70.92 | M23: Average Order Value
A24: ORD-0023 | B24: 46016 | C24: Customer 006 | D24: West | E24: Laptop Stand | F24: Accessories | G24: 3 | H24: 34.59 | I24: 0.1 | J24: 93.4 | K24: 19.41 | M24: =AVERAGE(J2:J178) -> 279.30723
A25: ORD-0024 | B25: 45809 | C25: Customer 015 | D25: East | E25: Keyboard | F25: Accessories | G25: 1 | H25: 47.88 | I25: 0.05 | J25: 45.49 | K25: 14.83
A26: ORD-0025 | B26: 45709 | C26: Customer 012 | D26: South | E26: Headset | F26: Audio | G26: 8 | H26: 65.2 | I26: 0.1 | J26: 469.41 | K26: 144.24 | M26: Profit Margin
A27: ORD-0026 | B27: 45844 | C27: Customer 049 | D27: South | E27: Monitor | F27: Displays | G27: 2 | H27: 217.13 | I27: 0 | J27: 434.26 | K27: 78.36 | M27: =13119.5/49437.38 -> 0.26537612
A28: ORD-0027 | B28: 45783 | C28: Customer 002 | D28: North | E28: Wireless Mouse | F28: Accessories | G28: 4 | H28: 20.42 | I28: 0 | J28: 81.68 | K28: 16.2
A29: ORD-0028 | B29: 45860 | C29: Customer 056 | D29: East | E29: USB-C Hub | F29: Accessories | G29: 2 | H29: 42.03 | I29: 0 | J29: 84.06 | K29: 20.64
A30: ORD-0029 | B30: 45897 | C30: Customer 016 | D30: North | E30: Laptop Stand | F30: Accessories | G30: 7 | H30: 36.7 | I30: 0.05 | J30: 244.04 | K30: 44.74
A31: ORD-0030 | B31: 45909 | C31: Customer 059 | D31: West | E31: Laptop Stand | F31: Accessories | G31: 4 | H31: 35.05 | I31: 0.05 | J31: 133.17 | K31: 27.74
A32: ORD-0031 | B32: 45965 | C32: Customer 041 | D32: North | E32: Keyboard | F32: Accessories | G32: 2 | H32: 48.09 | I32: 0 | J32: 96.19 | K32: 24.14
A33: ORD-0032 | B33: 45808 | C33: Customer 031 | D33: South | E33: Wireless Mouse | F33: Office | G33: 8 | H33: 32.09 | I33: 0.1 | J33: 231.05 | K33: 56.58
A34: ORD-0033 | B34: 45717 | C34: Customer 049 | D34: South | E34: Wireless Mouse | F34: Accessories | G34: 3 | H34: 21.04 | I34: 0 | J34: 63.13 | K34: 11.59
A35: ORD-0034 | B35: 45666 | C35: Customer 041 | D35: East | E35: Laptop Stand | F35: Accessories | G35: 8 | H35: 37.61 | I35: 0.05 | J35: 285.81 | K35: 58.15
A36: ORD-0035 | B36: 45818 | C36: Customer 024 | D36: West | E36: Keyboard | F36: Accessories | G36: 8 | H36: 50.66 | I36: 0.1 | J36: 364.77 | K36: 109.1
A37: ORD-0036 | B37: 45884 | C37: Customer 048 | D37: South | E37: Keyboard | F37: Accessories | G37: 1 | H37: 45.4 | I37: 0.1 | J37: 40.86 | K37: 10.57
A38: ORD-0037 | B38: 45851 | C38: Customer 054 | D38: East | E38: Laptop Stand | F38: Accessories | G38: 3 | H38: 37.65 | I38: 0 | J38: 112.96 | K38: 36.03
A39: ORD-0038 | B39: 45934 | C39: Customer 048 | D39: West | E39: Desk Lamp | F39: Office | G39: 5 | H39: 30.59 | I39: 0.1 | J39: 137.65 | K39: 45.77
... A178: ORD-0179 | B178: 45671 | C178: Customer 031 | D178: West | E178: USB-C Hub | F178: Accessories | G178: 7 | H178: 38.72 | I178: 0.05 | J178: 257.49 | K178: 64.65

Sheet Profit Margin Analysis
A1: Product | B1: Sales | C1: Profit | D1: Profit Margin%
A2: Monitor | B2: ='Pivot Table 1 Product'!B2 -> 21586.25 | C2: ='Pivot Table 4 Profit'!B2 -> 5452.34 | D2: =C2/B2 -> 0.25258394
A3: webcam | B3: ='Pivot Table 1 Product'!B3 -> 6450.39 | C3: ='Pivot Table 4 Profit'!B3 -> 1801.69 | D3: =C3/B3 -> 0.27931489
A4: Keyboard | B4: ='Pivot Table 1 Product'!B4 -> 4809.84 | C4: ='Pivot Table 4 Profit'!B4 -> 1293.37 | D4: =C4/B4 -> 0.26890084
A5: Laptop Stand | B5: ='Pivot Table 1 Product'!B5 -> 4405.39 | C5: ='Pivot Table 4 Profit'!B5 -> 1185.8 | D5: =C5/B5 -> 0.26917027
A6: Headset | B6: ='Pivot Table 1 Product'!B6 -> 3838.98 | C6: ='Pivot Table 4 Profit'!B6 -> 1023.31 | D6: =C6/B6 -> 0.26655778
A7: USB-C Hub | B7: ='Pivot Table 1 Product'!B7 -> 2995.33 | C7: ='Pivot Table 4 Profit'!B7 -> 875.48 | D7: =C7/B7 -> 0.29228165
A8: Desk Lamp | B8: ='Pivot Table 1 Product'!B8 -> 2779.62 | C8: ='Pivot Table 4 Profit'!B8 -> 768.32 | D8: =C8/B8 -> 0.27641188
A9: Wireless Mouse | B9: ='Pivot Table 1 Product'!B9 -> 2571.58 | C9: ='Pivot Table 4 Profit'!B9 -> 719.19 | D9: =C9/B9 -> 0.27966853

Sheet Discount Analysis
A1: Discount | B1: Total Sales | C1: Total Profit
A2: 0 | B2: =SUMIF(Analysis!$I$2:$I$178,0,Analysis!$J$2:$J$178) -> 17640.08 | C2: =SUMIF(Analysis!$I$2:$I$178,0,Analysis!$K$2:$K$178) -> 4720.5
A3: 0.05 | B3: =SUMIF(Analysis!$I$2:$I$178,0.05,Analysis!$J$2:$J$178) -> 11679.87 | C3: =SUMIF(Analysis!$I$2:$I$178,0.05,Analysis!$K$2:$K$178) -> 3148.29
A4: 0.1 | B4: =SUMIF(Analysis!$I$2:$I$178,0.1,Analysis!$J$2:$J$178) -> 12526.45 | C4: =SUMIF(Analysis!$I$2:$I$178,0.1,Analysis!$K$2:$K$178) -> 3485.97
A5: 0.15 | B5: =SUMIF(Analysis!$I$2:$I$178,0.15,Analysis!$J$2:$J$178) -> 7590.98 | C5: =SUMIF(Analysis!$I$2:$I$178,0.15,Analysis!$K$2:$K$178) -> 1764.74

Sheet Pivot Table 1 Product

Sheet Pivot Table 2 Category

Sheet Pivot Table 3 Region

Sheet Pivot Table 4 Profit

Sheet Pivot Table 5 Customer

Sheet Pivot Table 6 Quantity 
